Workbook

Sheet Supuestos
A1: AnunciaYA — Supuestos del modelo
A2: Ciudad: Puerto Peñasco · Horizonte: 12 meses · Moneda: MXN · Celdas en azul = editables
A4: PARÁMETROS
A5: Precio de membresía (mensual) | C5: 864
A6: Comisión de alta (pago único por negocio de vendedor) | C6: 400
A7: Número de vendedores (Etapa 2) | C7: 3
A8: Valor publicidad regalada Etapa 2 (3 meses · informativo) | C8: 537.3
A9: Meses que cubre 1 pago — Etapa 1 (cartera propia) | C9: 3 | D9: Etapa 1: paga al alta y vuelve a pagar desde el mes 4.
A10: Meses que cubre 1 pago — Etapa 2 (con vendedor) | C10: 2 | D10: Etapa 2: paga al alta y vuelve a pagar desde el mes 3.
A12: ESCALERA DE COMISIÓN MENSUAL (plana · por negocio activo del vendedor)
A13: Activos desde | B13: Activos hasta | C13: Comisión / mes
A14: 0 | B14: 10 | C14: 150
A15: 11 | B15: 20 | C15: 160
A16: 21 | B16: 30 | C16: 170
A17: 31 | B17: 40 | C17: 180
A18: 41 | B18: 50 | C18: 190
A19: 51 | B19: 60 | C19: 200
A20: 61 | B20: 70 | C20: 210
A21: 71 | B21: + | C21: 220
A22: La tarifa del tramo se cobra por CADA negocio activo del vendedor (plana).
A24: ALTAS DE NEGOCIOS POR MES (editable)
A25: Mes | B25: 1 | C25: 2 | D25: 3 | E25: 4 | F25: 5 | G25: 6 | H25: 7 | I25: 8 | J25: 9 | K25: 10 | L25: 11 | M25: 12 | N25: Total
A26: Altas propias (Etapa 1) | B26: 20 | C26: 20 | D26: 10 | E26: 0 | F26: 0 | G26: 0 | H26: 0 | I26: 0 | J26: 0 | K26: 0 | L26: 0 | M26: 0 | N26: =SUM(B26:M26) -> 50
A27: Altas vendedores (Etapa 2) | B27: 0 | C27: 0 | D27: 0 | E27: 8 | F27: 10 | G27: 12 | H27: 14 | I27: 14 | J27: 14 | K27: 14 | L27: 14 | M27: 14 | N27: =SUM(B27:M27) -> 114
A28: Total altas | B28: =B26+B27 -> 20 | C28: =C26+C27 -> 20 | D28: =D26+D27 -> 10 | E28: =E26+E27 -> 8 | F28: =F26+F27 -> 10 | G28: =G26+G27 -> 12 | H28: =H26+H27 -> 14 | I28: =I26+I27 -> 14 | ... M28: =M26+M27 -> 14 | N28: =SUM(B28:M28) -> 164

Sheet Proyección Puerto Peñasco
A1: Proyección de ingresos — Puerto Peñasco (Año 1)
A2: Moneda: MXN · Flujo de caja (ingreso en el mes del cobro) · Verde = enlace a Supuestos
A4: Mes | B4: =Supuestos!B25 -> 1 | C4: =Supuestos!C25 -> 2 | D4: =Supuestos!D25 -> 3 | E4: =Supuestos!E25 -> 4 | F4: =Supuestos!F25 -> 5 | G4: =Supuestos!G25 -> 6 | H4: =Supuestos!H25 -> 7 | I4: =Supuestos!I25 -> 8 | ... M4: =Supuestos!M25 -> 12 | N4: Año 1
A5: Periodo | B5: jul-26 | C5: ago-26 | D5: sep-26 | E5: oct-26 | F5: nov-26 | G5: dic-26 | H5: ene-27 | I5: feb-27 | J5: mar-27 | K5: abr-27 | L5: may-27 | M5: jun-27
A7: ALTAS
A8: Altas propias (Etapa 1) | B8: =Supuestos!B26 -> 20 | C8: =Supuestos!C26 -> 20 | D8: =Supuestos!D26 -> 10 | E8: =Supuestos!E26 -> 0 | F8: =Supuestos!F26 -> 0 | G8: =Supuestos!G26 -> 0 | H8: =Supuestos!H26 -> 0 | I8: =Supuestos!I26 -> 0 | ... M8: =Supuestos!M26 -> 0 | N8: =SUM(B8:M8) -> 50
A9: Altas vendedores (Etapa 2) | B9: =Supuestos!B27 -> 0 | C9: =Supuestos!C27 -> 0 | D9: =Supuestos!D27 -> 0 | E9: =Supuestos!E27 -> 8 | F9: =Supuestos!F27 -> 10 | G9: =Supuestos!G27 -> 12 | H9: =Supuestos!H27 -> 14 | I9: =Supuestos!I27 -> 14 | ... M9: =Supuestos!M27 -> 14 | N9: =SUM(B9:M9) -> 114
A10: Total altas | B10: =B8+B9 -> 20 | C10: =C8+C9 -> 20 | D10: =D8+D9 -> 10 | E10: =E8+E9 -> 8 | F10: =F8+F9 -> 10 | G10: =G8+G9 -> 12 | H10: =H8+H9 -> 14 | I10: =I8+I9 -> 14 | ... M10: =M8+M9 -> 14 | N10: =SUM(B10:M10) -> 164
A12: NEGOCIOS ACTIVOS (acumulado)
A13: Activos propios | B13: =B8 -> 20 | C13: =B13+C8 -> 40 | D13: =C13+D8 -> 50 | E13: =D13+E8 -> 50 | F13: =E13+F8 -> 50 | G13: =F13+G8 -> 50 | H13: =G13+H8 -> 50 | I13: =H13+I8 -> 50 | J13: =I13+J8 -> 50 | ... M13: =L13+M8 -> 50 | N13: =M13 -> 50
A14: Activos vendedores | B14: =B9 -> 0 | C14: =B14+C9 -> 0 | D14: =C14+D9 -> 0 | E14: =D14+E9 -> 8 | F14: =E14+F9 -> 18 | G14: =F14+G9 -> 30 | H14: =G14+H9 -> 44 | I14: =H14+I9 -> 58 | J14: =I14+J9 -> 72 | ... M14: =L14+M9 -> 114 | N14: =M14 -> 114
A15: Total activos | B15: =B13+B14 -> 20 | C15: =C13+C14 -> 40 | D15: =D13+D14 -> 50 | E15: =E13+E14 -> 58 | F15: =F13+F14 -> 68 | G15: =G13+G14 -> 80 | H15: =H13+H14 -> 94 | I15: =I13+I14 -> 108 | ... M15: =M13+M14 -> 164 | N15: =M15 -> 164
A16: Activos por vendedor (para el tramo) | B16: =B14/Supuestos!$C$7 -> 0 | C16: =C14/Supuestos!$C$7 -> 0 | D16: =D14/Supuestos!$C$7 -> 0 | E16: =E14/Supuestos!$C$7 -> 2.6666667 | F16: =F14/Supuestos!$C$7 -> 6 | G16: =G14/Supuestos!$C$7 -> 10 | H16: =H14/Supuestos!$C$7 -> 14.666667 | I16: =I14/Supuestos!$C$7 -> 19.333333 | ... M16: =M14/Supuestos!$C$7 -> 38
A18: INGRESOS (MXN)
A19: Pagos propios (#) | B19: =B53 -> 20 | C19: =C53 -> 20 | D19: =D53 -> 10 | E19: =E53 -> 20 | F19: =F53 -> 40 | G19: =G53 -> 50 | H19: =H53 -> 50 | I19: =I53 -> 50 | ... M19: =M53 -> 50 | N19: =SUM(B19:M19) -> 460
A20: Ingreso propios ($) | B20: =B19*Supuestos!$C$5 -> 17280 | C20: =C19*Supuestos!$C$5 -> 17280 | D20: =D19*Supuestos!$C$5 -> 8640 | E20: =E19*Supuestos!$C$5 -> 17280 | F20: =F19*Supuestos!$C$5 -> 34560 | G20: =G19*Supuestos!$C$5 -> 43200 | H20: =H19*Supuestos!$C$5 -> 43200 | I20: =I19*Supuestos!$C$5 -> 43200 | ... M20: =M19*Supuestos!$C$5 -> 43200 | N20: =SUM(B20:M20) -> 397440
A21: Pagos vendedores (#) | B21: =B68 -> 0 | C21: =C68 -> 0 | D21: =D68 -> 0 | E21: =E68 -> 8 | F21: =F68 -> 10 | G21: =G68 -> 20 | H21: =H68 -> 32 | I21: =I68 -> 44 | ... M21: =M68 -> 100 | N21: =SUM(B21:M21) -> 430
A22: Ingreso vendedores ($) | B22: =B21*Supuestos!$C$5 -> 0 | C22: =C21*Supuestos!$C$5 -> 0 | D22: =D21*Supuestos!$C$5 -> 0 | E22: =E21*Supuestos!$C$5 -> 6912 | F22: =F21*Supuestos!$C$5 -> 8640 | G22: =G21*Supuestos!$C$5 -> 17280 | H22: =H21*Supuestos!$C$5 -> 27648 | I22: =I21*Supuestos!$C$5 -> 38016 | ... M22: =M21*Supuestos!$C$5 -> 86400 | N22: =SUM(B22:M22) -> 371520
A23: Ingreso BRUTO ($) | B23: =B20+B22 -> 17280 | C23: =C20+C22 -> 17280 | D23: =D20+D22 -> 8640 | E23: =E20+E22 -> 24192 | F23: =F20+F22 -> 43200 | G23: =G20+G22 -> 60480 | H23: =H20+H22 -> 70848 | I23: =I20+I22 -> 81216 | ... M23: =M20+M22 -> 129600 | N23: =SUM(B23:M23) -> 768960
A25: COMISIONES A VENDEDORES (MXN)
A26: Comisión de alta ($) | B26: =B9*Supuestos!$C$6 -> 0 | C26: =C9*Supuestos!$C$6 -> 0 | D26: =D9*Supuestos!$C$6 -> 0 | E26: =E9*Supuestos!$C$6 -> 3200 | F26: =F9*Supuestos!$C$6 -> 4000 | G26: =G9*Supuestos!$C$6 -> 4800 | H26: =H9*Supuestos!$C$6 -> 5600 | I26: =I9*Supuestos!$C$6 -> 5600 | ... M26: =M9*Supuestos!$C$6 -> 5600 | N26: =SUM(B26:M26) -> 45600
A27: Recurrentes vendedores (#) | B27: =B21-B9 -> 0 | C27: =C21-C9 -> 0 | D27: =D21-D9 -> 0 | E27: =E21-E9 -> 0 | F27: =F21-F9 -> 0 | G27: =G21-G9 -> 8 | H27: =H21-H9 -> 18 | I27: =I21-I9 -> 30 | ... M27: =M21-M9 -> 86 | N27: =SUM(B27:M27) -> 316
A28: Tarifa escalera ($/negocio) | B28: =VLOOKUP(B16,Supuestos!$A$14:$C$21,3,TRUE) -> 150 | C28: =VLOOKUP(C16,Supuestos!$A$14:$C$21,3,TRUE) -> 150 | D28: =VLOOKUP(D16,Supuestos!$A$14:$C$21,3,TRUE) -> 150 | E28: =VLOOKUP(E16,Supuestos!$A$14:$C$21,3,TRUE) -> 150 | F28: =VLOOKUP(F16,Supuestos!$A$14:$C$21,3,TRUE) -> 150 | G28: =VLOOKUP(G16,Supuestos!$A$14:$C$21,3,TRUE) -> 150 | H28: =VLOOKUP(H16,Supuestos!$A$14:$C$21,3,TRUE) -> 160 | I28: =VLOOKUP(I16,Supuestos!$A$14:$C$21,3,TRUE) -> 160 | ... M28: =VLOOKUP(M16,Supuestos!$A$14:$C$21,3,TRUE) -> 180
A29: Comisión escalera ($) | B29: =B27*B28 -> 0 | C29: =C27*C28 -> 0 | D29: =D27*D28 -> 0 | E29: =E27*E28 -> 0 | F29: =F27*F28 -> 0 | G29: =G27*G28 -> 1200 | H29: =H27*H28 -> 2880 | I29: =I27*I28 -> 4800 | ... M29: =M27*M28 -> 15480 | N29: =SUM(B29:M29) -> 54660
A30: Total COMISIONES ($) | B30: =B26+B29 -> 0 | C30: =C26+C29 -> 0 | D30: =D26+D29 -> 0 | E30: =E26+E29 -> 3200 | F30: =F26+F29 -> 4000 | G30: =G26+G29 -> 6000 | H30: =H26+H29 -> 8480 | I30: =I26+I29 -> 10400 | ... M30: =M26+M29 -> 21080 | N30: =SUM(B30:M30) -> 100260
A32: RESULTADO (MXN)
A33: INGRESO NETO ($) | B33: =B23-B30 -> 17280 | C33: =C23-C30 -> 17280 | D33: =D23-D30 -> 8640 | E33: =E23-E30 -> 20992 | F33: =F23-F30 -> 39200 | G33: =G23-G30 -> 54480 | H33: =H23-H30 -> 62368 | I33: =I23-I30 -> 70816 | ... M33: =M23-M30 -> 108520 | N33: =SUM(B33:M33) -> 668700
A34: Ingreso neto acumulado ($) | B34: =B33 -> 17280 | C34: =B34+C33 -> 34560 | D34: =C34+D33 -> 43200 | E34: =D34+E33 -> 64192 | F34: =E34+F33 -> 103392 | G34: =F34+G33 -> 157872 | H34: =G34+H33 -> 220240 | I34: =H34+I33 -> 291056 | J34: =I34+J33 -> 371288 | ... M34: =L34+M33 -> 668700 | N34: =M34 -> 668700
A36: Memo · valor publicidad regalada ($, no resta al neto) | B36: =B9*Supuestos!$C$8 -> 0 | C36: =C9*Supuestos!$C$8 -> 0 | D36: =D9*Supuestos!$C$8 -> 0 | E36: =E9*Supuestos!$C$8 -> 4298.4 | F36: =F9*Supuestos!$C$8 -> 5373 | G36: =G9*Supuestos!$C$8 -> 6447.6 | H36: =H9*Supuestos!$C$8 -> 7522.2 | I36: =I9*Supuestos!$C$8 -> 7522.2 | ... M36: =M9*Supuestos!$C$8 -> 7522.2 | N36: =SUM(B36:M36) -> 61252.2
A39: CÁLCULO DE COHORTES — NO EDITAR
A40: Pagos propias · cohorte(fila) × mes(col) | B40: 1 | C40: 2 | D40: 3 | E40: 4 | F40: 5 | G40: 6 | H40: 7 | I40: 8 | J40: 9 | K40: 10 | L40: 11 | M40: 12
A41: Alta mes 1 | B41: =Supuestos!B26 -> 20 | C41: 0 | D41: 0 | E41: =Supuestos!B26 -> 20 | F41: =Supuestos!B26 -> 20 | G41: =Supuestos!B26 -> 20 | H41: =Supuestos!B26 -> 20 | I41: =Supuestos!B26 -> 20 | J41: =Supuestos!B26 -> 20 | K41: =Supuestos!B26 -> 20 | L41: =Supuestos!B26 -> 20 | M41: =Supuestos!B26 -> 20
A42: Alta mes 2 | B42: 0 | C42: =Supuestos!C26 -> 20 | D42: 0 | E42: 0 | F42: =Supuestos!C26 -> 20 | G42: =Supuestos!C26 -> 20 | H42: =Supuestos!C26 -> 20 | I42: =Supuestos!C26 -> 20 | J42: =Supuestos!C26 -> 20 | K42: =Supuestos!C26 -> 20 | L42: =Supuestos!C26 -> 20 | M42: =Supuestos!C26 -> 20
A43: Alta mes 3 | B43: 0 | C43: 0 | D43: =Supuestos!D26 -> 10 | E43: 0 | F43: 0 | G43: =Supuestos!D26 -> 10 | H43: =Supuestos!D26 -> 10 | I43: =Supuestos!D26 -> 10 | J43: =Supuestos!D26 -> 10 | K43: =Supuestos!D26 -> 10 | L43: =Supuestos!D26 -> 10 | M43: =Supuestos!D26 -> 10
A44: Alta mes 4 | B44: 0 | C44: 0 | D44: 0 | E44: =Supuestos!E26 -> 0 | F44: 0 | G44: 0 | H44: =Supuestos!E26 -> 0 | I44: =Supuestos!E26 -> 0 | J44: =Supuestos!E26 -> 0 | K44: =Supuestos!E26 -> 0 | L44: =Supuestos!E26 -> 0 | M44: =Supuestos!E26 -> 0
A45: Alta mes 5 | B45: 0 | C45: 0 | D45: 0 | E45: 0 | F45: =Supuestos!F26 -> 0 | G45: 0 | H45: 0 | I45: =Supuestos!F26 -> 0 | J45: =Supuestos!F26 -> 0 | K45: =Supuestos!F26 -> 0 | L45: =Supuestos!F26 -> 0 | M45: =Supuestos!F26 -> 0
A46: Alta mes 6 | B46: 0 | C46: 0 | D46: 0 | E46: 0 | F46: 0 | G46: =Supuestos!G26 -> 0 | H46: 0 | I46: 0 | J46: =Supuestos!G26 -> 0 | K46: =Supuestos!G26 -> 0 | L46: =Supuestos!G26 -> 0 | M46: =Supuestos!G26 -> 0
A47: Alta mes 7 | B47: 0 | C47: 0 | D47: 0 | E47: 0 | F47: 0 | G47: 0 | H47: =Supuestos!H26 -> 0 | I47: 0 | J47: 0 | K47: =Supuestos!H26 -> 0 | L47: =Supuestos!H26 -> 0 | M47: =Supuestos!H26 -> 0
A48: Alta mes 8 | B48: 0 | C48: 0 | D48: 0 | E48: 0 | F48: 0 | G48: 0 | H48: 0 | I48: =Supuestos!I26 -> 0 | J48: 0 | K48: 0 | L48: =Supuestos!I26 -> 0 | M48: =Supuestos!I26 -> 0
A49: Alta mes 9 | B49: 0 | C49: 0 | D49: 0 | E49: 0 | F49: 0 | G49: 0 | H49: 0 | I49: 0 | J49: =Supuestos!J26 -> 0 | K49: 0 | L49: 0 | M49: =Supuestos!J26 -> 0
...
